[2025-10-19 20:38:08,170] DEBUG asyncio: Using selector: SelectSelector
[2025-10-19 20:38:09,093] DEBUG asyncio: Using selector: SelectSelector
[2025-10-19 20:38:09,342] INFO django.utils.autoreload: Watching for file changes with StatReloader
[2025-10-19 20:38:09,514] INFO daphne.server: HTTP/2 support not enabled (install the http2 and tls Twisted extras)
[2025-10-19 20:38:09,514] INFO daphne.server: Configuring endpoint tcp:port=8000:interface=127.0.0.1
[2025-10-19 20:38:09,514] INFO daphne.server: Listening on TCP address 127.0.0.1:8000
[2025-10-19 20:43:07,694] INFO django.utils.autoreload: C:\Backend\authentication\urls.py changed, reloading.
[2025-10-19 20:43:08,772] DEBUG asyncio: Using selector: SelectSelector
[2025-10-19 20:43:09,085] INFO django.utils.autoreload: Watching for file changes with StatReloader
[2025-10-19 20:43:09,257] INFO daphne.server: HTTP/2 support not enabled (install the http2 and tls Twisted extras)
[2025-10-19 20:43:09,257] INFO daphne.server: Configuring endpoint tcp:port=8000:interface=127.0.0.1
[2025-10-19 20:43:09,257] INFO daphne.server: Listening on TCP address 127.0.0.1:8000
[2025-10-19 20:43:13,909] INFO django.utils.autoreload: C:\Backend\authentication\urls.py changed, reloading.
[2025-10-19 20:43:14,706] DEBUG asyncio: Using selector: SelectSelector
[2025-10-19 20:43:14,956] INFO django.utils.autoreload: Watching for file changes with StatReloader
[2025-10-19 20:43:15,097] INFO daphne.server: HTTP/2 support not enabled (install the http2 and tls Twisted extras)
[2025-10-19 20:43:15,097] INFO daphne.server: Configuring endpoint tcp:port=8000:interface=127.0.0.1
[2025-10-19 20:43:15,097] INFO daphne.server: Listening on TCP address 127.0.0.1:8000
[2025-10-19 20:43:41,751] INFO django.utils.autoreload: Watching for file changes with StatReloader
[2025-10-19 20:43:46,502] INFO django.utils.autoreload: C:\Backend\authentication\urls.py changed, reloading.
[2025-10-19 20:43:47,487] INFO django.utils.autoreload: Watching for file changes with StatReloader
[2025-10-19 20:43:52,244] INFO django.utils.autoreload: C:\Backend\authentication\urls.py changed, reloading.
[2025-10-19 20:43:53,321] INFO django.utils.autoreload: Watching for file changes with StatReloader
[2025-10-19 20:56:15,001] INFO django.utils.autoreload: Watching for file changes with StatReloader
[2025-10-19 21:04:35,234] INFO django.utils.autoreload: Watching for file changes with StatReloader
[2025-10-19 21:04:44,882] INFO django.utils.autoreload: Watching for file changes with StatReloader
[2025-10-19 21:04:49,311] INFO django.utils.autoreload: Watching for file changes with StatReloader
[2025-10-19 21:05:17,136] DEBUG asyncio: Using selector: SelectSelector
[2025-10-19 21:05:18,027] DEBUG asyncio: Using selector: SelectSelector
[2025-10-19 21:05:18,246] INFO django.utils.autoreload: Watching for file changes with StatReloader
[2025-10-19 21:05:18,403] INFO daphne.server: HTTP/2 support not enabled (install the http2 and tls Twisted extras)
[2025-10-19 21:05:18,418] INFO daphne.server: Configuring endpoint tcp:port=8000:interface=127.0.0.1
[2025-10-19 21:05:18,418] INFO daphne.server: Listening on TCP address 127.0.0.1:8000
[2025-10-19 21:06:54,839] DEBUG asyncio: Using selector: SelectSelector
[2025-10-19 21:06:55,870] DEBUG asyncio: Using selector: SelectSelector
[2025-10-19 21:06:56,198] INFO django.utils.autoreload: Watching for file changes with StatReloader
[2025-10-19 21:06:56,261] INFO daphne.server: HTTP/2 support not enabled (install the http2 and tls Twisted extras)
[2025-10-19 21:06:56,261] INFO daphne.server: Configuring endpoint tcp:port=8000:interface=0.0.0.0
[2025-10-19 21:06:56,261] INFO daphne.server: Listening on TCP address 0.0.0.0:8000
[2025-10-19 21:07:49,359] DEBUG asyncio: Using selector: SelectSelector
[2025-10-19 21:07:56,781] DEBUG asyncio: Using selector: SelectSelector
[2025-10-19 21:07:57,625] DEBUG asyncio: Using selector: SelectSelector
[2025-10-19 21:07:57,844] INFO django.utils.autoreload: Watching for file changes with StatReloader
[2025-10-19 21:07:57,984] INFO daphne.server: HTTP/2 support not enabled (install the http2 and tls Twisted extras)
[2025-10-19 21:07:57,984] INFO daphne.server: Configuring endpoint tcp:port=8000:interface=127.0.0.1
[2025-10-19 21:07:58,000] INFO daphne.server: Listening on TCP address 127.0.0.1:8000
[2025-10-19 21:08:05,044] DEBUG asyncio: Using selector: SelectSelector
[2025-10-19 21:11:54,263] DEBUG asyncio: Using selector: SelectSelector
[2025-10-19 21:15:24,294] INFO daphne.cli: Starting server at tcp:port=8000:interface=0.0.0.0
[2025-10-19 21:15:24,294] INFO daphne.server: HTTP/2 support not enabled (install the http2 and tls Twisted extras)
[2025-10-19 21:15:24,294] INFO daphne.server: Configuring endpoint tcp:port=8000:interface=0.0.0.0
[2025-10-19 21:15:24,294] INFO daphne.server: Listening on TCP address 0.0.0.0:8000
[2025-10-19 21:15:29,341] INFO daphne.server: Killed 0 pending application instances
[2025-10-19 21:15:34,763] DEBUG asyncio: Using selector: SelectSelector
[2025-10-19 21:15:35,653] DEBUG asyncio: Using selector: SelectSelector
[2025-10-19 21:15:35,872] INFO django.utils.autoreload: Watching for file changes with StatReloader
[2025-10-19 21:15:36,059] INFO daphne.server: HTTP/2 support not enabled (install the http2 and tls Twisted extras)
[2025-10-19 21:15:36,059] INFO daphne.server: Configuring endpoint tcp:port=8000:interface=127.0.0.1
[2025-10-19 21:15:36,059] INFO daphne.server: Listening on TCP address 127.0.0.1:8000
[2025-10-19 21:15:53,680] INFO django.utils.autoreload: Watching for file changes with StatReloader
[2025-10-19 21:16:38,866] WARNING django.request: Not Found: /
[2025-10-19 21:16:39,022] WARNING django.request: Not Found: /favicon.ico
[2025-10-19 21:16:55,847] DEBUG asyncio: Using selector: SelectSelector
[2025-10-19 21:17:00,174] DEBUG asyncio: Using selector: SelectSelector
[2025-10-19 21:17:04,488] DEBUG asyncio: Using selector: SelectSelector
[2025-10-19 21:17:05,316] DEBUG asyncio: Using selector: SelectSelector
[2025-10-19 21:17:05,534] INFO django.utils.autoreload: Watching for file changes with StatReloader
[2025-10-19 21:17:05,674] INFO daphne.server: HTTP/2 support not enabled (install the http2 and tls Twisted extras)
[2025-10-19 21:17:05,674] INFO daphne.server: Configuring endpoint tcp:port=8000:interface=127.0.0.1
[2025-10-19 21:17:05,674] INFO daphne.server: Listening on TCP address 127.0.0.1:8000
[2025-10-19 21:17:07,676] DEBUG daphne.http_protocol: HTTP b'GET' request for ['127.0.0.1', 52956]
[2025-10-19 21:17:08,043] WARNING django.request: Not Found: /
[2025-10-19 21:17:08,044] DEBUG daphne.http_protocol: HTTP 404 response started for ['127.0.0.1', 52956]
[2025-10-19 21:17:08,044] DEBUG daphne.http_protocol: HTTP close for ['127.0.0.1', 52956]
[2025-10-19 21:17:08,045] DEBUG daphne.http_protocol: HTTP response complete for ['127.0.0.1', 52956]
[2025-10-19 21:17:08,045] WARNING django.channels.server: [33mHTTP GET / 404 [0.37, 127.0.0.1:52956][0m
[2025-10-19 21:17:16,662] DEBUG daphne.http_protocol: HTTP b'GET' request for ['127.0.0.1', 52963]
[2025-10-19 21:17:16,797] DEBUG daphne.http_protocol: HTTP 200 response started for ['127.0.0.1', 52963]
[2025-10-19 21:17:16,797] DEBUG daphne.http_protocol: HTTP close for ['127.0.0.1', 52963]
[2025-10-19 21:17:16,797] DEBUG daphne.http_protocol: HTTP response complete for ['127.0.0.1', 52963]
[2025-10-19 21:17:16,798] INFO django.channels.server: [mHTTP GET /api/ 200 [0.14, 127.0.0.1:52963][0m
[2025-10-19 21:17:16,829] DEBUG daphne.http_protocol: HTTP b'GET' request for ['127.0.0.1', 52963]
[2025-10-19 21:17:16,831] DEBUG daphne.http_protocol: HTTP b'GET' request for ['127.0.0.1', 52964]
[2025-10-19 21:17:16,923] DEBUG daphne.http_protocol: HTTP b'GET' request for ['127.0.0.1', 52968]
[2025-10-19 21:17:16,941] DEBUG daphne.http_protocol: HTTP 200 response started for ['127.0.0.1', 52963]
[2025-10-19 21:17:16,942] DEBUG daphne.http_protocol: HTTP response chunk for ['127.0.0.1', 52963]
[2025-10-19 21:17:16,942] DEBUG daphne.http_protocol: HTTP close for ['127.0.0.1', 52963]
[2025-10-19 21:17:16,943] DEBUG daphne.http_protocol: HTTP response complete for ['127.0.0.1', 52963]
[2025-10-19 21:17:16,943] INFO django.channels.server: [mHTTP GET /static/rest_framework/css/bootstrap.min.css 200 [0.11, 127.0.0.1:52963][0m
[2025-10-19 21:17:16,946] DEBUG daphne.http_protocol: HTTP 200 response started for ['127.0.0.1', 52964]
[2025-10-19 21:17:16,948] DEBUG daphne.http_protocol: HTTP response chunk for ['127.0.0.1', 52964]
[2025-10-19 21:17:16,953] DEBUG daphne.http_protocol: HTTP b'GET' request for ['127.0.0.1', 52963]
[2025-10-19 21:17:16,957] DEBUG daphne.http_protocol: HTTP close for ['127.0.0.1', 52964]
[2025-10-19 21:17:16,958] DEBUG daphne.http_protocol: HTTP response complete for ['127.0.0.1', 52964]
[2025-10-19 21:17:16,959] INFO django.channels.server: [mHTTP GET /static/rest_framework/css/bootstrap-tweaks.css 200 [0.13, 127.0.0.1:52964][0m
[2025-10-19 21:17:16,962] DEBUG daphne.http_protocol: HTTP b'GET' request for ['127.0.0.1', 52964]
[2025-10-19 21:17:16,964] DEBUG daphne.http_protocol: HTTP 200 response started for ['127.0.0.1', 52968]
[2025-10-19 21:17:16,965] DEBUG daphne.http_protocol: HTTP response chunk for ['127.0.0.1', 52968]
[2025-10-19 21:17:16,966] DEBUG daphne.http_protocol: HTTP close for ['127.0.0.1', 52968]
[2025-10-19 21:17:16,967] DEBUG daphne.http_protocol: HTTP response complete for ['127.0.0.1', 52968]
[2025-10-19 21:17:16,969] INFO django.channels.server: [mHTTP GET /static/rest_framework/css/prettify.css 200 [0.05, 127.0.0.1:52968][0m
[2025-10-19 21:17:16,970] DEBUG daphne.http_protocol: HTTP b'GET' request for ['127.0.0.1', 52968]
[2025-10-19 21:17:16,975] DEBUG daphne.http_protocol: HTTP 200 response started for ['127.0.0.1', 52963]
[2025-10-19 21:17:16,976] DEBUG daphne.http_protocol: HTTP response chunk for ['127.0.0.1', 52963]
[2025-10-19 21:17:16,980] DEBUG daphne.http_protocol: HTTP close for ['127.0.0.1', 52963]
[2025-10-19 21:17:16,980] DEBUG daphne.http_protocol: HTTP response complete for ['127.0.0.1', 52963]
[2025-10-19 21:17:16,983] INFO django.channels.server: [mHTTP GET /static/rest_framework/css/default.css 200 [0.03, 127.0.0.1:52963][0m
[2025-10-19 21:17:16,986] DEBUG daphne.http_protocol: HTTP b'GET' request for ['127.0.0.1', 52963]
[2025-10-19 21:17:16,991] DEBUG daphne.http_protocol: HTTP 200 response started for ['127.0.0.1', 52964]
[2025-10-19 21:17:16,993] DEBUG daphne.http_protocol: HTTP response chunk for ['127.0.0.1', 52964]
[2025-10-19 21:17:16,994] DEBUG daphne.http_protocol: HTTP close for ['127.0.0.1', 52964]
[2025-10-19 21:17:16,995] DEBUG daphne.http_protocol: HTTP response complete for ['127.0.0.1', 52964]
[2025-10-19 21:17:16,996] INFO django.channels.server: [mHTTP GET /static/rest_framework/js/jquery-3.5.1.min.js 200 [0.03, 127.0.0.1:52964][0m
[2025-10-19 21:17:17,002] DEBUG daphne.http_protocol: HTTP b'GET' request for ['127.0.0.1', 52964]
[2025-10-19 21:17:17,009] DEBUG daphne.http_protocol: HTTP 200 response started for ['127.0.0.1', 52968]
[2025-10-19 21:17:17,029] DEBUG daphne.http_protocol: HTTP response chunk for ['127.0.0.1', 52968]
[2025-10-19 21:17:17,030] DEBUG daphne.http_protocol: HTTP close for ['127.0.0.1', 52968]
[2025-10-19 21:17:17,031] DEBUG daphne.http_protocol: HTTP response complete for ['127.0.0.1', 52968]
[2025-10-19 21:17:17,039] INFO django.channels.server: [mHTTP GET /static/rest_framework/js/ajax-form.js 200 [0.07, 127.0.0.1:52968][0m
[2025-10-19 21:17:17,041] DEBUG daphne.http_protocol: HTTP b'GET' request for ['127.0.0.1', 52968]
[2025-10-19 21:17:17,043] DEBUG daphne.http_protocol: HTTP 200 response started for ['127.0.0.1', 52963]
[2025-10-19 21:17:17,044] DEBUG daphne.http_protocol: HTTP response chunk for ['127.0.0.1', 52963]
[2025-10-19 21:17:17,045] DEBUG daphne.http_protocol: HTTP close for ['127.0.0.1', 52963]
[2025-10-19 21:17:17,046] DEBUG daphne.http_protocol: HTTP response complete for ['127.0.0.1', 52963]
[2025-10-19 21:17:17,048] INFO django.channels.server: [mHTTP GET /static/rest_framework/js/csrf.js 200 [0.06, 127.0.0.1:52963][0m
[2025-10-19 21:17:17,052] DEBUG daphne.http_protocol: HTTP b'GET' request for ['127.0.0.1', 52963]
[2025-10-19 21:17:17,056] DEBUG daphne.http_protocol: HTTP 200 response started for ['127.0.0.1', 52964]
[2025-10-19 21:17:17,057] DEBUG daphne.http_protocol: HTTP response chunk for ['127.0.0.1', 52964]
[2025-10-19 21:17:17,058] DEBUG daphne.http_protocol: HTTP close for ['127.0.0.1', 52964]
[2025-10-19 21:17:17,059] DEBUG daphne.http_protocol: HTTP response complete for ['127.0.0.1', 52964]
[2025-10-19 21:17:17,064] INFO django.channels.server: [mHTTP GET /static/rest_framework/js/bootstrap.min.js 200 [0.06, 127.0.0.1:52964][0m
[2025-10-19 21:17:17,068] DEBUG daphne.http_protocol: HTTP b'GET' request for ['127.0.0.1', 52964]
[2025-10-19 21:17:17,071] DEBUG daphne.http_protocol: HTTP 200 response started for ['127.0.0.1', 52968]
[2025-10-19 21:17:17,076] DEBUG daphne.http_protocol: HTTP response chunk for ['127.0.0.1', 52968]
[2025-10-19 21:17:17,077] DEBUG daphne.http_protocol: HTTP close for ['127.0.0.1', 52968]
[2025-10-19 21:17:17,077] DEBUG daphne.http_protocol: HTTP response complete for ['127.0.0.1', 52968]
[2025-10-19 21:17:17,078] INFO django.channels.server: [mHTTP GET /static/rest_framework/js/prettify-min.js 200 [0.04, 127.0.0.1:52968][0m
[2025-10-19 21:17:17,091] DEBUG daphne.http_protocol: HTTP 200 response started for ['127.0.0.1', 52963]
[2025-10-19 21:17:17,092] DEBUG daphne.http_protocol: HTTP response chunk for ['127.0.0.1', 52963]
[2025-10-19 21:17:17,095] DEBUG daphne.http_protocol: HTTP close for ['127.0.0.1', 52963]
[2025-10-19 21:17:17,105] DEBUG daphne.http_protocol: HTTP response complete for ['127.0.0.1', 52963]
[2025-10-19 21:17:17,119] INFO django.channels.server: [mHTTP GET /static/rest_framework/js/default.js 200 [0.07, 127.0.0.1:52963][0m
[2025-10-19 21:17:17,123] DEBUG daphne.http_protocol: HTTP 200 response started for ['127.0.0.1', 52964]
[2025-10-19 21:17:17,124] DEBUG daphne.http_protocol: HTTP response chunk for ['127.0.0.1', 52964]
[2025-10-19 21:17:17,125] DEBUG daphne.http_protocol: HTTP close for ['127.0.0.1', 52964]
[2025-10-19 21:17:17,126] DEBUG daphne.http_protocol: HTTP response complete for ['127.0.0.1', 52964]
[2025-10-19 21:17:17,126] INFO django.channels.server: [mHTTP GET /static/rest_framework/img/grid.png 200 [0.06, 127.0.0.1:52964][0m
[2025-10-19 21:18:00,687] WARNING django.request: Not Found: /
[2025-10-19 21:23:34,170] CRITICAL daphne.server: Listen failure: Couldn't listen on 0.0.0.0:8001: [WinError 10048] Only one usage of each socket address (protocol/network address/port) is normally permitted.
[2025-10-19 21:24:17,967] CRITICAL daphne.server: Listen failure: Couldn't listen on 0.0.0.0:8001: [WinError 10048] Only one usage of each socket address (protocol/network address/port) is normally permitted.
[2025-10-19 21:29:49,498] CRITICAL daphne.server: Listen failure: Couldn't listen on 0.0.0.0:8000: [WinError 10048] Only one usage of each socket address (protocol/network address/port) is normally permitted.
[2025-10-19 21:30:54,842] CRITICAL daphne.server: Listen failure: Couldn't listen on 0.0.0.0:8000: [WinError 10048] Only one usage of each socket address (protocol/network address/port) is normally permitted.
[2025-10-19 21:34:13,865] CRITICAL daphne.server: Listen failure: Couldn't listen on 0.0.0.0:9000: [WinError 10048] Only one usage of each socket address (protocol/network address/port) is normally permitted.
[2025-10-19 21:46:32,749] WARNING django.request: Not Found: /favicon.ico
[2025-10-19 21:46:43,497] WARNING django.request: Not Found: /
[2025-10-19 23:22:34,239] INFO django.utils.autoreload: Watching for file changes with StatReloader
[2025-10-19 23:26:34,695] INFO django.utils.autoreload: Watching for file changes with StatReloader
[2025-10-19 23:28:12,788] INFO django.utils.autoreload: Watching for file changes with StatReloader
[2025-10-19 23:30:58,018] INFO django.utils.autoreload: C:\Backend\config\settings.py changed, reloading.
[2025-10-19 23:31:02,003] INFO django.utils.autoreload: Watching for file changes with StatReloader
[2025-10-19 23:31:12,080] INFO django.utils.autoreload: Watching for file changes with StatReloader
[2025-10-19 23:39:04,605] INFO django.utils.autoreload: Watching for file changes with StatReloader
[2025-10-19 23:47:21,972] WARNING django.request: Not Found: /static/rest_framework/js/jquery-3.7.1.min.js
[2025-10-19 23:47:22,772] WARNING django.request: Not Found: /static/rest_framework/js/load-ajax-form.js
[2025-10-19 23:47:24,682] WARNING django.request: Not Found: /
[2025-10-19 23:47:56,553] WARNING django.request: Not Found: /static/rest_framework/js/jquery-3.7.1.min.js
[2025-10-19 23:47:56,934] WARNING django.request: Not Found: /static/rest_framework/js/load-ajax-form.js
[2025-10-19 23:51:31,790] INFO django.utils.autoreload: Watching for file changes with StatReloader
[2025-10-19 23:51:45,244] INFO django.utils.autoreload: Watching for file changes with StatReloader
[2025-10-19 23:52:56,322] INFO django.utils.autoreload: Watching for file changes with StatReloader
[2025-10-19 23:55:23,333] INFO django.utils.autoreload: Watching for file changes with StatReloader
[2025-10-19 23:57:08,798] CRITICAL daphne.server: Listen failure: Couldn't listen on 0.0.0.0:8000: [WinError 10048] Only one usage of each socket address (protocol/network address/port) is normally permitted.
[2025-10-19 23:57:56,874] WARNING django.request: Not Found: /static/rest_framework/js/jquery-3.7.1.min.js
[2025-10-19 23:57:56,974] WARNING django.request: Not Found: /static/rest_framework/js/load-ajax-form.js
[2025-10-20 00:02:00,274] INFO django.utils.autoreload: Watching for file changes with StatReloader
[2025-10-20 00:24:57,153] INFO django.utils.autoreload: Watching for file changes with StatReloader
[2025-10-20 01:24:09,444] INFO django.utils.autoreload: Watching for file changes with StatReloader
[2025-10-20 01:24:47,208] WARNING django.request: Not Found: /static/rest_framework/js/jquery-3.7.1.min.js
[2025-10-20 01:24:47,318] WARNING django.request: Not Found: /static/rest_framework/js/load-ajax-form.js
[2025-10-20 01:52:13,622] ERROR huey.consumer.Scheduler: Error reading schedule.
Traceback (most recent call last):
  File "C:\Backend\venv\Lib\site-packages\redis\connection.py", line 389, in connect_check_health
    sock = self.retry.call_with_retry(
           ^^^^^^^^^^^^^^^^^^^^^^^^^^^
  File "C:\Backend\venv\Lib\site-packages\redis\retry.py", line 105, in call_with_retry
    return do()
           ^^^^
  File "C:\Backend\venv\Lib\site-packages\redis\connection.py", line 390, in <lambda>
    lambda: self._connect(), lambda error: self.disconnect(error)
            ^^^^^^^^^^^^^^^
  File "C:\Backend\venv\Lib\site-packages\redis\connection.py", line 803, in _connect
    raise err
  File "C:\Backend\venv\Lib\site-packages\redis\connection.py", line 787, in _connect
    sock.connect(socket_address)
ConnectionRefusedError: [WinError 10061] No connection could be made because the target machine actively refused it

During handling of the above exception, another exception occurred:

Traceback (most recent call last):
  File "C:\Backend\venv\Lib\site-packages\huey\consumer.py", line 164, in loop
    task_list = self.huey.read_schedule(now)
                ^^^^^^^^^^^^^^^^^^^^^^^^^^^^
  File "C:\Backend\venv\Lib\site-packages\huey\api.py", line 608, in read_schedule
    for msg in self.storage.read_schedule(timestamp):
               ^^^^^^^^^^^^^^^^^^^^^^^^^^^^^^^^^^^^^
  File "C:\Backend\venv\Lib\site-packages\huey\storage.py", line 448, in read_schedule
    tasks = self._pop(keys=[self.schedule_key], args=[unix_ts])
            ^^^^^^^^^^^^^^^^^^^^^^^^^^^^^^^^^^^^^^^^^^^^^^^^^^^
  File "C:\Backend\venv\Lib\site-packages\redis\commands\core.py", line 5702, in __call__
    return client.evalsha(self.sha, len(keys), *args)
           ^^^^^^^^^^^^^^^^^^^^^^^^^^^^^^^^^^^^^^^^^^
  File "C:\Backend\venv\Lib\site-packages\redis\commands\core.py", line 5911, in evalsha
    return self._evalsha("EVALSHA", sha, numkeys, *keys_and_args)
           ^^^^^^^^^^^^^^^^^^^^^^^^^^^^^^^^^^^^^^^^^^^^^^^^^^^^^^
  File "C:\Backend\venv\Lib\site-packages\redis\commands\core.py", line 5895, in _evalsha
    return self.execute_command(command, sha, numkeys, *keys_and_args)
           ^^^^^^^^^^^^^^^^^^^^^^^^^^^^^^^^^^^^^^^^^^^^^^^^^^^^^^^^^^^
  File "C:\Backend\venv\Lib\site-packages\redis\client.py", line 621, in execute_command
    return self._execute_command(*args, **options)
           ^^^^^^^^^^^^^^^^^^^^^^^^^^^^^^^^^^^^^^^
  File "C:\Backend\venv\Lib\site-packages\redis\client.py", line 627, in _execute_command
    conn = self.connection or pool.get_connection()
                              ^^^^^^^^^^^^^^^^^^^^^
  File "C:\Backend\venv\Lib\site-packages\redis\utils.py", line 195, in wrapper
    return func(*args, **kwargs)
           ^^^^^^^^^^^^^^^^^^^^^
  File "C:\Backend\venv\Lib\site-packages\redis\connection.py", line 1533, in get_connection
    connection.connect()
  File "C:\Backend\venv\Lib\site-packages\redis\connection.py", line 380, in connect
    self.connect_check_health(check_health=True)
  File "C:\Backend\venv\Lib\site-packages\redis\connection.py", line 397, in connect_check_health
    raise ConnectionError(self._error_message(e))
redis.exceptions.ConnectionError: Error 10061 connecting to 127.0.0.1:6380. No connection could be made because the target machine actively refused it.
[2025-10-20 01:52:15,653] ERROR huey.consumer.Scheduler: Error reading schedule.
Traceback (most recent call last):
  File "C:\Backend\venv\Lib\site-packages\redis\connection.py", line 389, in connect_check_health
    sock = self.retry.call_with_retry(
           ^^^^^^^^^^^^^^^^^^^^^^^^^^^
  File "C:\Backend\venv\Lib\site-packages\redis\retry.py", line 105, in call_with_retry
    return do()
           ^^^^
  File "C:\Backend\venv\Lib\site-packages\redis\connection.py", line 390, in <lambda>
    lambda: self._connect(), lambda error: self.disconnect(error)
            ^^^^^^^^^^^^^^^
  File "C:\Backend\venv\Lib\site-packages\redis\connection.py", line 803, in _connect
    raise err
  File "C:\Backend\venv\Lib\site-packages\redis\connection.py", line 787, in _connect
    sock.connect(socket_address)
ConnectionRefusedError: [WinError 10061] No connection could be made because the target machine actively refused it

During handling of the above exception, another exception occurred:

Traceback (most recent call last):
  File "C:\Backend\venv\Lib\site-packages\huey\consumer.py", line 164, in loop
    task_list = self.huey.read_schedule(now)
                ^^^^^^^^^^^^^^^^^^^^^^^^^^^^
  File "C:\Backend\venv\Lib\site-packages\huey\api.py", line 608, in read_schedule
    for msg in self.storage.read_schedule(timestamp):
               ^^^^^^^^^^^^^^^^^^^^^^^^^^^^^^^^^^^^^
  File "C:\Backend\venv\Lib\site-packages\huey\storage.py", line 448, in read_schedule
    tasks = self._pop(keys=[self.schedule_key], args=[unix_ts])
            ^^^^^^^^^^^^^^^^^^^^^^^^^^^^^^^^^^^^^^^^^^^^^^^^^^^
  File "C:\Backend\venv\Lib\site-packages\redis\commands\core.py", line 5702, in __call__
    return client.evalsha(self.sha, len(keys), *args)
           ^^^^^^^^^^^^^^^^^^^^^^^^^^^^^^^^^^^^^^^^^^
  File "C:\Backend\venv\Lib\site-packages\redis\commands\core.py", line 5911, in evalsha
    return self._evalsha("EVALSHA", sha, numkeys, *keys_and_args)
           ^^^^^^^^^^^^^^^^^^^^^^^^^^^^^^^^^^^^^^^^^^^^^^^^^^^^^^
  File "C:\Backend\venv\Lib\site-packages\redis\commands\core.py", line 5895, in _evalsha
    return self.execute_command(command, sha, numkeys, *keys_and_args)
           ^^^^^^^^^^^^^^^^^^^^^^^^^^^^^^^^^^^^^^^^^^^^^^^^^^^^^^^^^^^
  File "C:\Backend\venv\Lib\site-packages\redis\client.py", line 621, in execute_command
    return self._execute_command(*args, **options)
           ^^^^^^^^^^^^^^^^^^^^^^^^^^^^^^^^^^^^^^^
  File "C:\Backend\venv\Lib\site-packages\redis\client.py", line 627, in _execute_command
    conn = self.connection or pool.get_connection()
                              ^^^^^^^^^^^^^^^^^^^^^
  File "C:\Backend\venv\Lib\site-packages\redis\utils.py", line 195, in wrapper
    return func(*args, **kwargs)
           ^^^^^^^^^^^^^^^^^^^^^
  File "C:\Backend\venv\Lib\site-packages\redis\connection.py", line 1533, in get_connection
    connection.connect()
  File "C:\Backend\venv\Lib\site-packages\redis\connection.py", line 380, in connect
    self.connect_check_health(check_health=True)
  File "C:\Backend\venv\Lib\site-packages\redis\connection.py", line 397, in connect_check_health
    raise ConnectionError(self._error_message(e))
redis.exceptions.ConnectionError: Error 10061 connecting to 127.0.0.1:6380. No connection could be made because the target machine actively refused it.
[2025-10-20 01:52:17,684] ERROR huey.consumer.Scheduler: Error reading schedule.
Traceback (most recent call last):
  File "C:\Backend\venv\Lib\site-packages\redis\connection.py", line 389, in connect_check_health
    sock = self.retry.call_with_retry(
           ^^^^^^^^^^^^^^^^^^^^^^^^^^^
  File "C:\Backend\venv\Lib\site-packages\redis\retry.py", line 105, in call_with_retry
    return do()
           ^^^^
  File "C:\Backend\venv\Lib\site-packages\redis\connection.py", line 390, in <lambda>
    lambda: self._connect(), lambda error: self.disconnect(error)
            ^^^^^^^^^^^^^^^
  File "C:\Backend\venv\Lib\site-packages\redis\connection.py", line 803, in _connect
    raise err
  File "C:\Backend\venv\Lib\site-packages\redis\connection.py", line 787, in _connect
    sock.connect(socket_address)
ConnectionRefusedError: [WinError 10061] No connection could be made because the target machine actively refused it

During handling of the above exception, another exception occurred:

Traceback (most recent call last):
  File "C:\Backend\venv\Lib\site-packages\huey\consumer.py", line 164, in loop
    task_list = self.huey.read_schedule(now)
                ^^^^^^^^^^^^^^^^^^^^^^^^^^^^
  File "C:\Backend\venv\Lib\site-packages\huey\api.py", line 608, in read_schedule
    for msg in self.storage.read_schedule(timestamp):
               ^^^^^^^^^^^^^^^^^^^^^^^^^^^^^^^^^^^^^
  File "C:\Backend\venv\Lib\site-packages\huey\storage.py", line 448, in read_schedule
    tasks = self._pop(keys=[self.schedule_key], args=[unix_ts])
            ^^^^^^^^^^^^^^^^^^^^^^^^^^^^^^^^^^^^^^^^^^^^^^^^^^^
  File "C:\Backend\venv\Lib\site-packages\redis\commands\core.py", line 5702, in __call__
    return client.evalsha(self.sha, len(keys), *args)
           ^^^^^^^^^^^^^^^^^^^^^^^^^^^^^^^^^^^^^^^^^^
  File "C:\Backend\venv\Lib\site-packages\redis\commands\core.py", line 5911, in evalsha
    return self._evalsha("EVALSHA", sha, numkeys, *keys_and_args)
           ^^^^^^^^^^^^^^^^^^^^^^^^^^^^^^^^^^^^^^^^^^^^^^^^^^^^^^
  File "C:\Backend\venv\Lib\site-packages\redis\commands\core.py", line 5895, in _evalsha
    return self.execute_command(command, sha, numkeys, *keys_and_args)
           ^^^^^^^^^^^^^^^^^^^^^^^^^^^^^^^^^^^^^^^^^^^^^^^^^^^^^^^^^^^
  File "C:\Backend\venv\Lib\site-packages\redis\client.py", line 621, in execute_command
    return self._execute_command(*args, **options)
           ^^^^^^^^^^^^^^^^^^^^^^^^^^^^^^^^^^^^^^^
  File "C:\Backend\venv\Lib\site-packages\redis\client.py", line 627, in _execute_command
    conn = self.connection or pool.get_connection()
                              ^^^^^^^^^^^^^^^^^^^^^
  File "C:\Backend\venv\Lib\site-packages\redis\utils.py", line 195, in wrapper
    return func(*args, **kwargs)
           ^^^^^^^^^^^^^^^^^^^^^
  File "C:\Backend\venv\Lib\site-packages\redis\connection.py", line 1533, in get_connection
    connection.connect()
  File "C:\Backend\venv\Lib\site-packages\redis\connection.py", line 380, in connect
    self.connect_check_health(check_health=True)
  File "C:\Backend\venv\Lib\site-packages\redis\connection.py", line 397, in connect_check_health
    raise ConnectionError(self._error_message(e))
redis.exceptions.ConnectionError: Error 10061 connecting to 127.0.0.1:6380. No connection could be made because the target machine actively refused it.
[2025-10-20 01:52:19,731] ERROR huey.consumer.Scheduler: Error reading schedule.
Traceback (most recent call last):
  File "C:\Backend\venv\Lib\site-packages\redis\connection.py", line 389, in connect_check_health
    sock = self.retry.call_with_retry(
           ^^^^^^^^^^^^^^^^^^^^^^^^^^^
  File "C:\Backend\venv\Lib\site-packages\redis\retry.py", line 105, in call_with_retry
    return do()
           ^^^^
  File "C:\Backend\venv\Lib\site-packages\redis\connection.py", line 390, in <lambda>
    lambda: self._connect(), lambda error: self.disconnect(error)
            ^^^^^^^^^^^^^^^
  File "C:\Backend\venv\Lib\site-packages\redis\connection.py", line 803, in _connect
    raise err
  File "C:\Backend\venv\Lib\site-packages\redis\connection.py", line 787, in _connect
    sock.connect(socket_address)
ConnectionRefusedError: [WinError 10061] No connection could be made because the target machine actively refused it

During handling of the above exception, another exception occurred:

Traceback (most recent call last):
  File "C:\Backend\venv\Lib\site-packages\huey\consumer.py", line 164, in loop
    task_list = self.huey.read_schedule(now)
                ^^^^^^^^^^^^^^^^^^^^^^^^^^^^
  File "C:\Backend\venv\Lib\site-packages\huey\api.py", line 608, in read_schedule
    for msg in self.storage.read_schedule(timestamp):
               ^^^^^^^^^^^^^^^^^^^^^^^^^^^^^^^^^^^^^
  File "C:\Backend\venv\Lib\site-packages\huey\storage.py", line 448, in read_schedule
    tasks = self._pop(keys=[self.schedule_key], args=[unix_ts])
            ^^^^^^^^^^^^^^^^^^^^^^^^^^^^^^^^^^^^^^^^^^^^^^^^^^^
  File "C:\Backend\venv\Lib\site-packages\redis\commands\core.py", line 5702, in __call__
    return client.evalsha(self.sha, len(keys), *args)
           ^^^^^^^^^^^^^^^^^^^^^^^^^^^^^^^^^^^^^^^^^^
  File "C:\Backend\venv\Lib\site-packages\redis\commands\core.py", line 5911, in evalsha
    return self._evalsha("EVALSHA", sha, numkeys, *keys_and_args)
           ^^^^^^^^^^^^^^^^^^^^^^^^^^^^^^^^^^^^^^^^^^^^^^^^^^^^^^
  File "C:\Backend\venv\Lib\site-packages\redis\commands\core.py", line 5895, in _evalsha
    return self.execute_command(command, sha, numkeys, *keys_and_args)
           ^^^^^^^^^^^^^^^^^^^^^^^^^^^^^^^^^^^^^^^^^^^^^^^^^^^^^^^^^^^
  File "C:\Backend\venv\Lib\site-packages\redis\client.py", line 621, in execute_command
    return self._execute_command(*args, **options)
           ^^^^^^^^^^^^^^^^^^^^^^^^^^^^^^^^^^^^^^^
  File "C:\Backend\venv\Lib\site-packages\redis\client.py", line 627, in _execute_command
    conn = self.connection or pool.get_connection()
                              ^^^^^^^^^^^^^^^^^^^^^
  File "C:\Backend\venv\Lib\site-packages\redis\utils.py", line 195, in wrapper
    return func(*args, **kwargs)
           ^^^^^^^^^^^^^^^^^^^^^
  File "C:\Backend\venv\Lib\site-packages\redis\connection.py", line 1533, in get_connection
    connection.connect()
  File "C:\Backend\venv\Lib\site-packages\redis\connection.py", line 380, in connect
    self.connect_check_health(check_health=True)
  File "C:\Backend\venv\Lib\site-packages\redis\connection.py", line 397, in connect_check_health
    raise ConnectionError(self._error_message(e))
redis.exceptions.ConnectionError: Error 10061 connecting to 127.0.0.1:6380. No connection could be made because the target machine actively refused it.
[2025-10-20 01:52:21,778] ERROR huey.consumer.Scheduler: Error reading schedule.
Traceback (most recent call last):
  File "C:\Backend\venv\Lib\site-packages\redis\connection.py", line 389, in connect_check_health
    sock = self.retry.call_with_retry(
           ^^^^^^^^^^^^^^^^^^^^^^^^^^^
  File "C:\Backend\venv\Lib\site-packages\redis\retry.py", line 105, in call_with_retry
    return do()
           ^^^^
  File "C:\Backend\venv\Lib\site-packages\redis\connection.py", line 390, in <lambda>
    lambda: self._connect(), lambda error: self.disconnect(error)
            ^^^^^^^^^^^^^^^
  File "C:\Backend\venv\Lib\site-packages\redis\connection.py", line 803, in _connect
    raise err
  File "C:\Backend\venv\Lib\site-packages\redis\connection.py", line 787, in _connect
    sock.connect(socket_address)
ConnectionRefusedError: [WinError 10061] No connection could be made because the target machine actively refused it

During handling of the above exception, another exception occurred:

Traceback (most recent call last):
  File "C:\Backend\venv\Lib\site-packages\huey\consumer.py", line 164, in loop
    task_list = self.huey.read_schedule(now)
                ^^^^^^^^^^^^^^^^^^^^^^^^^^^^
  File "C:\Backend\venv\Lib\site-packages\huey\api.py", line 608, in read_schedule
    for msg in self.storage.read_schedule(timestamp):
               ^^^^^^^^^^^^^^^^^^^^^^^^^^^^^^^^^^^^^
  File "C:\Backend\venv\Lib\site-packages\huey\storage.py", line 448, in read_schedule
    tasks = self._pop(keys=[self.schedule_key], args=[unix_ts])
            ^^^^^^^^^^^^^^^^^^^^^^^^^^^^^^^^^^^^^^^^^^^^^^^^^^^
  File "C:\Backend\venv\Lib\site-packages\redis\commands\core.py", line 5702, in __call__
    return client.evalsha(self.sha, len(keys), *args)
           ^^^^^^^^^^^^^^^^^^^^^^^^^^^^^^^^^^^^^^^^^^
  File "C:\Backend\venv\Lib\site-packages\redis\commands\core.py", line 5911, in evalsha
    return self._evalsha("EVALSHA", sha, numkeys, *keys_and_args)
           ^^^^^^^^^^^^^^^^^^^^^^^^^^^^^^^^^^^^^^^^^^^^^^^^^^^^^^
  File "C:\Backend\venv\Lib\site-packages\redis\commands\core.py", line 5895, in _evalsha
    return self.execute_command(command, sha, numkeys, *keys_and_args)
           ^^^^^^^^^^^^^^^^^^^^^^^^^^^^^^^^^^^^^^^^^^^^^^^^^^^^^^^^^^^
  File "C:\Backend\venv\Lib\site-packages\redis\client.py", line 621, in execute_command
    return self._execute_command(*args, **options)
           ^^^^^^^^^^^^^^^^^^^^^^^^^^^^^^^^^^^^^^^
  File "C:\Backend\venv\Lib\site-packages\redis\client.py", line 627, in _execute_command
    conn = self.connection or pool.get_connection()
                              ^^^^^^^^^^^^^^^^^^^^^
  File "C:\Backend\venv\Lib\site-packages\redis\utils.py", line 195, in wrapper
    return func(*args, **kwargs)
           ^^^^^^^^^^^^^^^^^^^^^
  File "C:\Backend\venv\Lib\site-packages\redis\connection.py", line 1533, in get_connection
    connection.connect()
  File "C:\Backend\venv\Lib\site-packages\redis\connection.py", line 380, in connect
    self.connect_check_health(check_health=True)
  File "C:\Backend\venv\Lib\site-packages\redis\connection.py", line 397, in connect_check_health
    raise ConnectionError(self._error_message(e))
redis.exceptions.ConnectionError: Error 10061 connecting to 127.0.0.1:6380. No connection could be made because the target machine actively refused it.
[2025-10-20 01:52:29,481] ERROR huey.consumer.Scheduler: Error reading schedule.
Traceback (most recent call last):
  File "C:\Backend\venv\Lib\site-packages\redis\connection.py", line 389, in connect_check_health
    sock = self.retry.call_with_retry(
           ^^^^^^^^^^^^^^^^^^^^^^^^^^^
  File "C:\Backend\venv\Lib\site-packages\redis\retry.py", line 105, in call_with_retry
    return do()
           ^^^^
  File "C:\Backend\venv\Lib\site-packages\redis\connection.py", line 390, in <lambda>
    lambda: self._connect(), lambda error: self.disconnect(error)
            ^^^^^^^^^^^^^^^
  File "C:\Backend\venv\Lib\site-packages\redis\connection.py", line 803, in _connect
    raise err
  File "C:\Backend\venv\Lib\site-packages\redis\connection.py", line 787, in _connect
    sock.connect(socket_address)
ConnectionRefusedError: [WinError 10061] No connection could be made because the target machine actively refused it

During handling of the above exception, another exception occurred:

Traceback (most recent call last):
  File "C:\Backend\venv\Lib\site-packages\huey\consumer.py", line 164, in loop
    task_list = self.huey.read_schedule(now)
                ^^^^^^^^^^^^^^^^^^^^^^^^^^^^
  File "C:\Backend\venv\Lib\site-packages\huey\api.py", line 608, in read_schedule
    for msg in self.storage.read_schedule(timestamp):
               ^^^^^^^^^^^^^^^^^^^^^^^^^^^^^^^^^^^^^
  File "C:\Backend\venv\Lib\site-packages\huey\storage.py", line 448, in read_schedule
    tasks = self._pop(keys=[self.schedule_key], args=[unix_ts])
            ^^^^^^^^^^^^^^^^^^^^^^^^^^^^^^^^^^^^^^^^^^^^^^^^^^^
  File "C:\Backend\venv\Lib\site-packages\redis\commands\core.py", line 5702, in __call__
    return client.evalsha(self.sha, len(keys), *args)
           ^^^^^^^^^^^^^^^^^^^^^^^^^^^^^^^^^^^^^^^^^^
  File "C:\Backend\venv\Lib\site-packages\redis\commands\core.py", line 5911, in evalsha
    return self._evalsha("EVALSHA", sha, numkeys, *keys_and_args)
           ^^^^^^^^^^^^^^^^^^^^^^^^^^^^^^^^^^^^^^^^^^^^^^^^^^^^^^
  File "C:\Backend\venv\Lib\site-packages\redis\commands\core.py", line 5895, in _evalsha
    return self.execute_command(command, sha, numkeys, *keys_and_args)
           ^^^^^^^^^^^^^^^^^^^^^^^^^^^^^^^^^^^^^^^^^^^^^^^^^^^^^^^^^^^
  File "C:\Backend\venv\Lib\site-packages\redis\client.py", line 621, in execute_command
    return self._execute_command(*args, **options)
           ^^^^^^^^^^^^^^^^^^^^^^^^^^^^^^^^^^^^^^^
  File "C:\Backend\venv\Lib\site-packages\redis\client.py", line 627, in _execute_command
    conn = self.connection or pool.get_connection()
                              ^^^^^^^^^^^^^^^^^^^^^
  File "C:\Backend\venv\Lib\site-packages\redis\utils.py", line 195, in wrapper
    return func(*args, **kwargs)
           ^^^^^^^^^^^^^^^^^^^^^
  File "C:\Backend\venv\Lib\site-packages\redis\connection.py", line 1533, in get_connection
    connection.connect()
  File "C:\Backend\venv\Lib\site-packages\redis\connection.py", line 380, in connect
    self.connect_check_health(check_health=True)
  File "C:\Backend\venv\Lib\site-packages\redis\connection.py", line 397, in connect_check_health
    raise ConnectionError(self._error_message(e))
redis.exceptions.ConnectionError: Error 10061 connecting to 127.0.0.1:6380. No connection could be made because the target machine actively refused it.
[2025-10-20 01:52:31,512] ERROR huey.consumer.Scheduler: Error reading schedule.
Traceback (most recent call last):
  File "C:\Backend\venv\Lib\site-packages\redis\connection.py", line 389, in connect_check_health
    sock = self.retry.call_with_retry(
           ^^^^^^^^^^^^^^^^^^^^^^^^^^^
  File "C:\Backend\venv\Lib\site-packages\redis\retry.py", line 105, in call_with_retry
    return do()
           ^^^^
  File "C:\Backend\venv\Lib\site-packages\redis\connection.py", line 390, in <lambda>
    lambda: self._connect(), lambda error: self.disconnect(error)
            ^^^^^^^^^^^^^^^
  File "C:\Backend\venv\Lib\site-packages\redis\connection.py", line 803, in _connect
    raise err
  File "C:\Backend\venv\Lib\site-packages\redis\connection.py", line 787, in _connect
    sock.connect(socket_address)
ConnectionRefusedError: [WinError 10061] No connection could be made because the target machine actively refused it

During handling of the above exception, another exception occurred:

Traceback (most recent call last):
  File "C:\Backend\venv\Lib\site-packages\huey\consumer.py", line 164, in loop
    task_list = self.huey.read_schedule(now)
                ^^^^^^^^^^^^^^^^^^^^^^^^^^^^
  File "C:\Backend\venv\Lib\site-packages\huey\api.py", line 608, in read_schedule
    for msg in self.storage.read_schedule(timestamp):
               ^^^^^^^^^^^^^^^^^^^^^^^^^^^^^^^^^^^^^
  File "C:\Backend\venv\Lib\site-packages\huey\storage.py", line 448, in read_schedule
    tasks = self._pop(keys=[self.schedule_key], args=[unix_ts])
            ^^^^^^^^^^^^^^^^^^^^^^^^^^^^^^^^^^^^^^^^^^^^^^^^^^^
  File "C:\Backend\venv\Lib\site-packages\redis\commands\core.py", line 5702, in __call__
    return client.evalsha(self.sha, len(keys), *args)
           ^^^^^^^^^^^^^^^^^^^^^^^^^^^^^^^^^^^^^^^^^^
  File "C:\Backend\venv\Lib\site-packages\redis\commands\core.py", line 5911, in evalsha
    return self._evalsha("EVALSHA", sha, numkeys, *keys_and_args)
           ^^^^^^^^^^^^^^^^^^^^^^^^^^^^^^^^^^^^^^^^^^^^^^^^^^^^^^
  File "C:\Backend\venv\Lib\site-packages\redis\commands\core.py", line 5895, in _evalsha
    return self.execute_command(command, sha, numkeys, *keys_and_args)
           ^^^^^^^^^^^^^^^^^^^^^^^^^^^^^^^^^^^^^^^^^^^^^^^^^^^^^^^^^^^
  File "C:\Backend\venv\Lib\site-packages\redis\client.py", line 621, in execute_command
    return self._execute_command(*args, **options)
           ^^^^^^^^^^^^^^^^^^^^^^^^^^^^^^^^^^^^^^^
  File "C:\Backend\venv\Lib\site-packages\redis\client.py", line 627, in _execute_command
    conn = self.connection or pool.get_connection()
                              ^^^^^^^^^^^^^^^^^^^^^
  File "C:\Backend\venv\Lib\site-packages\redis\utils.py", line 195, in wrapper
    return func(*args, **kwargs)
           ^^^^^^^^^^^^^^^^^^^^^
  File "C:\Backend\venv\Lib\site-packages\redis\connection.py", line 1533, in get_connection
    connection.connect()
  File "C:\Backend\venv\Lib\site-packages\redis\connection.py", line 380, in connect
    self.connect_check_health(check_health=True)
  File "C:\Backend\venv\Lib\site-packages\redis\connection.py", line 397, in connect_check_health
    raise ConnectionError(self._error_message(e))
redis.exceptions.ConnectionError: Error 10061 connecting to 127.0.0.1:6380. No connection could be made because the target machine actively refused it.
[2025-10-20 02:28:51,651] INFO django.utils.autoreload: Watching for file changes with StatReloader
[2025-10-20 02:29:38,592] CRITICAL daphne.server: Listen failure: Couldn't listen on 0.0.0.0:8000: [WinError 10048] Only one usage of each socket address (protocol/network address/port) is normally permitted.
[2025-10-20 02:30:33,841] INFO django.channels.worker: Running worker for channels ['authentication']
